Workbook

Sheet Riepilogo di esportazione
B3: Questo documento è stato esportato da Numbers. Tutte le tabelle sono state convertite in un foglio di lavoro di Excel. Tutti gli altri oggetti di ciascun foglio di Numbers sono stati collocati in fogli di lavoro separati. Nota che i calcoli delle formule potrebbero differire in Excel.
B7: Nome del foglio di Numbers | C7: Nome della tabella di Numbers | D7: Nome foglio di lavoro Excel
B9: LEGGIMI
C10: Tabella 1 | D10: LEGGIMI
B11: Riepilogo
C12: Tabella 1 | D12: Riepilogo
B13: Tutti i giocatori
C14: Tabella 1 | D14: Tutti i giocatori
B15: Portieri
C16: Tabella 1 | D16: Portieri
B17: Difensori
C18: Tabella 1 | D18: Difensori
B19: Centrocampisti
C20: Tabella 1 | D20: Centrocampisti
B21: Attaccanti
C22: Tabella 1 | D22: Attaccanti

Sheet LEGGIMI
A1: Guida asta Fantacalcio — Serie A 2026/27
A2: Listone Gazzetta + gerarchie e stato fisico aggiornati al 5 settembre 2026
B4: Come usarlo | C4: Parti dai fogli per ruolo, filtra la fascia e poi usa Score asta, titolarità, tag, rigoristi e stato fisico. La checkbox stretta tra Score asta e Scommessa serve per segnare manualmente i tuoi obiettivi e filtrarli. Le stelline identificano le scommesse: ★ prudente, ★★ interessante, ★★★ forte upside.
B6: Perimetro | C6: 590 calciatori presenti nel listone pubblico Gazzetta 2026/27 consultato il 5 settembre, dopo la chiusura del mercato. Squadre e quotazioni provengono direttamente dal listone aggiornato.
B8: Fasce | C8: Quattro fasce calcolate separatamente per ruolo: TOP = primo 10%; SEMITOP = fino al 25%; TERZA FASCIA = fino al 50%; QUARTA FASCIA = restante 50%. Lo score privilegia la quotazione Gazzetta e corregge per titolarità, rendimento 2025/26, rigori/punizioni, indicazioni Gazzetta e indisponibilità.
B10: Titolarità | C10: È un’etichetta, non un numero. “Titolare fisso” = XI tipo Gazzetta e impiego nelle prime due giornate; “Titolare probabile” = XI tipo; “Ballottaggio (Nome)” = testa-a-testa esplicito nelle probabili formazioni della 3ª giornata; gli altri sono rotazione/riserva.
B12: Scommesse | C12: Le stelline partono dalle sezioni “possibili sorprese” delle schede squadra Gazzetta; completano l'elenco alcuni Under 23 già nell'XI tipo e nuove entrate consigliate. ★★★ richiede anche titolarità e profilo giovane/non-top.
B14: Stato fisico | C14: “Rischio infortunio” viene usato quando il giocatore risulta attualmente indisponibile nella pagina Gazzetta della 3ª giornata. Quando è indicata una giornata di rientro, aggiungo tra parentesi il mese del calendario Serie A 2026/27, per esempio “Rientro alla 14 (dicembre)”. Non è una previsione medica per l’intera stagione.
B16: Dati 26/27 | C16: Presenze, medie, gol, assist e rigori sono una fotografia dopo due giornate e pesano poco nello score. I dati 2025/26 servono per distinguere garanzie e portatori di bonus.
B18: Aggiornamento mercato | C18: Il file è stato rigenerato sul listone Gazzetta disponibile il 5 settembre, dopo la chiusura del mercato: i ceduti fuori dalla Serie A sono esclusi e i nuovi inserimenti sono inclusi.
B21: Legenda fasce | D21: Copertura dati
B22: TOP | D22: Listone Gazzetta | E22: 590
B23: SEMITOP | D23: Profili/statistiche abbinati | E23: 533
B24: TERZA FASCIA | D24: Rose esterne abbinate | E24: 511
B25: QUARTA FASCIA | D25: Schede squadra Gazzetta | E25: 20
D26: Squadre con gerarchie piazzati | E26: 20
D27: Indisponibili censiti | E27: 52
D28: Ballottaggi espliciti | E28: 39
B30: Fonti
B31: Listone e quotazioni Gazzetta | C31: https://www.gazzetta.it/calcio/fantanews/lista-giocatori-fantacalcio-serie-a-2026-27/ | H31: Ufficiale; consultato 05/09/2026
B32: Schede squadre Gazzetta | C32: https://www.gazzetta.it/calcio/fantanews/05-08-2026/fantacalcio-2026-27-titolari-rigoristi-formazioni-squadre-serie-a.shtml | H32: XI tipo, consigli e sorprese; consultate 05/09/2026
B33: Probabili formazioni Gazzetta | C33: https://www.gazzetta.it/Calcio/prob_form/ | H33: Ballottaggi della 3ª giornata; aggiornati 05/09/2026
B34: Rigoristi e punizioni Gazzetta | C34: https://www.gazzetta.it/calcio/fantanews/strumenti-fantacalcio/rigoristi/17-08-2026/rigoristi-serie-a-fantacalcio-tiratori-calci-da-fermo-punizioni.shtml | H34: Gerarchie; consultate 05/09/2026
B35: Indisponibili Gazzetta | C35: https://www.gazzetta.it/calcio/fantanews/strumenti-fantacalcio/indisponibili/lista/ | H35: Stato 3ª giornata; consultato 05/09/2026
B36: Statistiche Fantacalcio.it | C36: https://www.fantacalcio.it/statistiche-serie-a/2026-27/italia | H36: Anagrafica e dati 2026/27; consultati 05/09/2026
B37: Statistiche 2025/26 | C37: https://www.fantacalcio.it/statistiche-serie-a/2025-26/italia | H37: Storico rendimento; consultato 05/09/2026
B38: Rose e anagrafiche di controllo | C38: https://serieaspelare.se/ | H38: Controllo incrociato; consultato 05/09/2026
B39: Anagrafiche residue | C39: https://www.transfermarkt.com/ | H39: Usato solo per i nomi non coperti dalle fonti precedenti
B40: Calendario Serie A 2026/27 | C40: https://www.legaseriea.it/serie-a/news/calendario-della-serie-a-enilive-2026-27 | H40: Mese associato alla giornata di rientro

Sheet Riepilogo
A1: Riepilogo asta
A2: Conteggi automatici per ruolo e fascia; usa i filtri nei fogli giocatori per la selezione finale
A4: Ruolo | B4: Totale | C4: TOP | D4: SEMITOP | E4: TERZA FASCIA | F4: QUARTA FASCIA | G4: Scommesse | H4: Titolari | I4: Indisponibili
A5: Portieri | B5: {=COUNTA('Portieri'!$E$5:$E$76)} -> 72 | C5: {=COUNTIF('Portieri'!$A$5:$A$76,"TOP")} -> 8 | D5: {=COUNTIF('Portieri'!$A$5:$A$76,"SEMITOP")} -> 10 | E5: {=COUNTIF('Portieri'!$A$5:$A$76,"TERZA FASCIA")} -> 18 | F5: {=COUNTIF('Portieri'!$A$5:$A$76,"QUARTA FASCIA")} -> 36 | G5: {=COUNTIF('Portieri'!$D$5:$D$76,"<>")} -> 4 | H5: {=COUNTIF('Portieri'!$H$5:$H$76,"Titolare*")} -> 19 | I5: {=COUNTIF('Portieri'!$O$5:$O$76,"<>")} -> 1
A6: Difensori | B6: {=COUNTA('Difensori'!$E$5:$E$203)} -> 199 | C6: {=COUNTIF('Difensori'!$A$5:$A$203,"TOP")} -> 20 | D6: {=COUNTIF('Difensori'!$A$5:$A$203,"SEMITOP")} -> 30 | E6: {=COUNTIF('Difensori'!$A$5:$A$203,"TERZA FASCIA")} -> 50 | F6: {=COUNTIF('Difensori'!$A$5:$A$203,"QUARTA FASCIA")} -> 99 | G6: {=COUNTIF('Difensori'!$D$5:$D$203,"<>")} -> 40 | H6: {=COUNTIF('Difensori'!$H$5:$H$203,"Titolare*")} -> 71 | I6: {=COUNTIF('Difensori'!$O$5:$O$203,"<>")} -> 17
A7: Centrocampisti | B7: {=COUNTA('Centrocampisti'!$E$5:$E$203)} -> 199 | C7: {=COUNTIF('Centrocampisti'!$A$5:$A$203,"TOP")} -> 20 | D7: {=COUNTIF('Centrocampisti'!$A$5:$A$203,"SEMITOP")} -> 30 | E7: {=COUNTIF('Centrocampisti'!$A$5:$A$203,"TERZA FASCIA")} -> 50 | F7: {=COUNTIF('Centrocampisti'!$A$5:$A$203,"QUARTA FASCIA")} -> 99 | G7: {=COUNTIF('Centrocampisti'!$D$5:$D$203,"<>")} -> 47 | H7: {=COUNTIF('Centrocampisti'!$H$5:$H$203,"Titolare*")} -> 66 | I7: {=COUNTIF('Centrocampisti'!$O$5:$O$203,"<>")} -> 22
A8: Attaccanti | B8: {=COUNTA('Attaccanti'!$E$5:$E$124)} -> 120 | C8: {=COUNTIF('Attaccanti'!$A$5:$A$124,"TOP")} -> 12 | D8: {=COUNTIF('Attaccanti'!$A$5:$A$124,"SEMITOP")} -> 18 | E8: {=COUNTIF('Attaccanti'!$A$5:$A$124,"TERZA FASCIA")} -> 30 | F8: {=COUNTIF('Attaccanti'!$A$5:$A$124,"QUARTA FASCIA")} -> 60 | G8: {=COUNTIF('Attaccanti'!$D$5:$D$124,"<>")} -> 35 | H8: {=COUNTIF('Attaccanti'!$H$5:$H$124,"Titolare*")} -> 30 | I8: {=COUNTIF('Attaccanti'!$O$5:$O$124,"<>")} -> 12
A9: TOTALE | B9: {=SUM(B5:B8)} -> 590 | C9: {=SUM(C5:C8)} -> 60 | D9: {=SUM(D5:D8)} -> 88 | E9: {=SUM(E5:E8)} -> 148 | F9: {=SUM(F5:F8)} -> 294 | G9: {=SUM(G5:G8)} -> 126 | H9: {=SUM(H5:H8)} -> 186 | I9: {=SUM(I5:I8)} -> 52
A12: Lettura rapida
A13: • Score asta: indice 0–100, utile per ordinare; non è un prezzo d'acquisto.
A14: • Quotazione Gazzetta: valore ufficiale del listone pubblico consultato il 5 settembre.
A15: • Squadra attuale: controllo post-mercato aggiornato per orientarsi sulle rose definitive.
A16: • Infortuni: nei fogli per ruolo filtra la colonna “Stato fisico / rientro” ed escludi le celle vuote. Controlla sempre la data di rientro prima dell’asta.

Sheet Tutti i giocatori
A1: Tutti i giocatori
A2: 590 nomi del listone Gazzetta 2026/27 — ordinati per ruolo, fascia e score
A4: Fascia | B4: Score asta | C4: ✓ | D4: Scommessa | E4: Nome | F4: Squadra attuale | G4: Quotazione Gazzetta | H4: Titolarità | I4: Tag | J4: Età | K4: Nazionalità | L4: Piede | M4: Rigorista | N4: Punizioni | O4: Stato fisico / rientro | P4: PG 26/27 | Q4: MV 26/27 | R4: FM 26/27 | S4: Gol 26/27 | T4: Assist 26/27 | U4: Rigori 26/27 | V4: PG 25/26 | W4: MV 25/26 | X4: FM 25/26 | Y4: Gol 25/26 | Z4: Assist 25/26 | AA4: Rigori 25/26 | AB4: Scheda Gazzetta | AC4: Scheda statistiche | AD4: Fonte gerarchie
A5: TOP | B5: 91.3 | C5: FALSE | E5: Svilar M. | F5: Roma | G5: 40 | H5: Titolare fisso | I5: Titolare fisso · Consigliato Gazzetta · Garanzia voto | J5: 27 | K5: Serbia, Belgio | L5: Dx | P5: 2 | Q5: 6.25 | R5: 6.25 | S5: 0 | T5: 0 | U5: 0/0 | V5: 38 | W5: 6.32 | X5: 5.5 | Y5: 0 | Z5: 0 | AA5: 0/0 | AB5: Apri | AC5: Apri | AD5: Apri
A6: TOP | B6: 90.4 | C6: FALSE | E6: Carnesecchi M. | F6: Atalanta | G6: 35 | H6: Titolare fisso | I6: Titolare fisso · Consigliato Gazzetta · Garanzia voto | J6: 26 | K6: Italia | L6: Dx | P6: 2 | Q6: 6.75 | R6: 6.75 | S6: 0 | T6: 1 | U6: 0/0 | V6: 37 | W6: 6.43 | X6: 5.65 | Y6: 0 | Z6: 0 | AA6: 0/0 | AB6: Apri | AC6: Apri | AD6: Apri
A7: TOP | B7: 85.3 | C7: FALSE | E7: Maignan M. | F7: Milan | G7: 34 | H7: Titolare fisso | I7: Titolare fisso · Garanzia voto | J7: 31 | K7: Francia, Guyana Francese | L7: Dx | P7: 2 | Q7: 6 | R7: 5.5 | S7: 0 | T7: 0 | U7: 0/0 | V7: 37 | W7: 6.3 | X7: 5.46 | Y7: 0 | Z7: 0 | AA7: 0/0 | AB7: Apri | AC7: Apri | AD7: Apri
A8: TOP | B8: 84 | C8: FALSE | E8: Martinez J. | F8: Inter | G8: 29 | H8: Titolare fisso | I8: Titolare fisso · Consigliato Gazzetta | J8: 28 | K8: Spagna | L8: Dx | P8: 2 | Q8: 6 | R8: 5.5 | S8: 0 | T8: 0 | U8: 0/0 | V8: 5 | W8: 6 | X8: 5.2 | Y8: 0 | Z8: 0 | AA8: 0/0 | AB8: Apri | AC8: Apri | AD8: Apri
A9: TOP | B9: 83.7 | C9: FALSE | E9: Vicario G. | F9: Juventus | G9: 32 | H9: Titolare fisso | I9: Titolare fisso · Consigliato Gazzetta · Novità / ritorno in A | J9: 29 | K9: Italia | L9: Dx | P9: 2 | Q9: 6.5 | R9: 6.5 | S9: 0 | T9: 0 | U9: 0/0 | AB9: Apri | AC9: Apri | AD9: Apri
A10: TOP | B10: 83.7 | C10: FALSE | E10: Butez J. | F10: Como | G10: 31 | H10: Titolare fisso | I10: Titolare fisso · Garanzia voto | J10: 31 | K10: Francia | L10: Dx | P10: 3 | Q10: 6.17 | R10: 5.17 | S10: 0 | T10: 0 | U10: 0/0 | V10: 38 | W10: 6.11 | X10: 5.41 | Y10: 0 | Z10: 1 | AA10: 0/0 | AB10: Apri | AC10: Apri | AD10: Apri
A11: TOP | B11: 78.2 | C11: FALSE | E11: Skorupski L. | F11: Bologna | G11: 22 | H11: Titolare fisso | I11: Titolare fisso | J11: 35 | K11: Polonia | L11: Dx | P11: 2 | Q11: 5.25 | R11: 4.25 | S11: 0 | T11: 0 | U11: 0/0 | V11: 18 | W11: 6.14 | X11: 5.22 | Y11: 0 | Z11: 0 | AA11: 0/0 | AB11: Apri | AC11: Apri | AD11: Apri
A12: TOP | B12: 77.5 | C12: FALSE | E12: Caprile E. | F12: Cagliari | G12: 21 | H12: Titolare fisso | I12: Titolare fisso · Garanzia voto | J12: 25 | K12: Italia | L12: Dx | P12: 2 | Q12: 6.5 | R12: 6 | S12: 0 | T12: 0 | U12: 0/0 | V12: 38 | W12: 6.29 | X12: 4.87 | Y12: 0 | Z12: 0 | AA12: 0/0 | AB12: Apri | AC12: Apri | AD12: Apri
A13: SEMITOP | B13: 77.4 | C13: FALSE | E13: Mandas C. | F13: Lazio | G13: 29 | H13: Titolare fisso | I13: Titolare fisso · Novità / ritorno in A | J13: 24 | K13: Grecia | L13: Dx | P13: 2 | Q13: 6.5 | R13: 6.5 | S13: 0 | T13: 0 | U13: 0/0 | V13: 0 | W13: 0 | X13: 0 | Y13: 0 | Z13: 0 | AA13: 0/0 | AB13: Apri | AC13: Apri | AD13: Apri
A14: SEMITOP | B14: 75.1 | C14: FALSE | E14: Meret A. | F14: Napoli | G14: 15 | H14: Titolare fisso | I14: Titolare fisso · Consigliato Gazzetta | J14: 29 | K14: Italia | L14: Sx | P14: 2 | Q14: 6 | R14: 5 | S14: 0 | T14: 0 | U14: 0/0 | V14: 11 | W14: 6.18 | X14: 5.14 | Y14: 0 | Z14: 1 | AA14: 0/0 | AB14: Apri | AC14: Apri | AD14: Apri
A15: SEMITOP | B15: 75.1 | C15: FALSE | E15: Bijlow J. | F15: Genoa | G15: 17 | H15: Titolare fisso | I15: Titolare fisso | J15: 28 | K15: Olanda | L15: Dx | P15: 3 | Q15: 5.33 | R15: 3 | S15: 0 | T15: 0 | U15: 0/0 | V15: 16 | W15: 6.09 | X15: 4.81 | Y15: 0 | Z15: 0 | AA15: 0/0 | AB15: Apri | AC15: Apri | AD15: Apri
A16: SEMITOP | B16: 74.3 | C16: FALSE | E16: Okoye M. | F16: Udinese | G16: 16 | H16: Titolare fisso | I16: Titolare fisso · Garanzia voto | J16: 27 | K16: Nigeria, Germania | L16: Dx | P16: 2 | Q16: 6.25 | R16: 4.75 | S16: 0 | T16: 0 | U16: 0/0 | V16: 30 | W16: 6.08 | X16: 5.1 | Y16: 0 | Z16: 1 | AA16: 0/0 | AB16: Apri | AC16: Apri | AD16: Apri
A17: SEMITOP | B17: 73.5 | C17: FALSE | D17: ★★ | E17: Perri L. | F17: Torino | G17: 22 | H17: Titolare probabile | I17: Titolare probabile · Scommessa Gazzetta · Novità / ritorno in A | J17: 28 | K17: Brasile, Italia | L17: Dx | P17: 0 | Q17: 0 | R17: 0 | S17: 0 | T17: 0 | U17: 0/0 | AB17: Apri | AC17: Apri | AD17: Apri
A18: SEMITOP | B18: 72.5 | C18: FALSE | E18: Falcone W. | F18: Lecce | G18: 15 | H18: Titolare fisso | I18: Titolare fisso · Garanzia voto | J18: 31 | K18: Italia | L18: Dx | P18: 2 | Q18: 6.25 | R18: 4.25 | S18: 0 | T18: 0 | U18: 0/0 | V18: 38 | W18: 6.45 | X18: 5.26 | Y18: 0 | Z18: 0 | AA18: 0/0 | AB18: Apri | AC18: Apri | AD18: Apri
A19: SEMITOP | B19: 72.3 | C19: FALSE | E19: De Gea D. | F19: Fiorentina | G19: 15 | H19: Titolare fisso | I19: Titolare fisso · Garanzia voto | J19: 35 | K19: Spagna | L19: Dx | P19: 2 | Q19: 5 | R19: 1.5 | S19: 0 | T19: 0 | U19: 0/0 | V19: 37 | W19: 6.22 | X19: 4.97 | Y19: 0 | Z19: 0 | AA19: 0/0 | AB19: Apri | AC19: Apri | AD19: Apri
A20: SEMITOP | B20: 72.1 | C20: FALSE | E20: Muric A. | F20: Sassuolo | G20: 15 | H20: Titolare fisso | I20: Titolare fisso · Garanzia voto | J20: 27 | K20: Kosovo, Montenegro | L20: Dx | P20: 2 | Q20: 6.5 | R20: 5 | S20: 0 | T20: 0 | U20: 0/0 | V20: 32 | W20: 6.06 | X20: 4.75 | Y20: 0 | Z20: 0 | AA20: 0/0 | AB20: Apri | AC20: Apri | AD20: Apri
A21: SEMITOP | B21: 70.9 | C21: FALSE | E21: Milinkovic Savic V. | F21: Napoli | G21: 28 | H21: Rotazione / riserva | I21: Rotazione / riserva · Consigliato Gazzetta | J21: 29 | K21: Serbia, Spagna | L21: Dx | P21: 0 | Q21: 0 | R21: 0 | S21: 0 | T21: 0 | U21: 0/0 | V21: 27 | W21: 6.17 | X21: 5.61 | Y21: 0 | Z21: 0 | AA21: 0/0 | AB21: Apri | AC21: Apri | AD21: Apri
A22: SEMITOP | B22: 67.6 | C22: FALSE | D22: ★★★ | E22: Palmisani L. | F22: Frosinone | G22: 14 | H22: Titolare fisso | I22: Titolare fisso · Scommessa Gazzetta · Under 23 · Novità / ritorno in A | J22: 22 | K22: Italia | L22: Dx | P22: 2 | Q22: 6.25 | R22: 5.75 | S22: 0 | T22: 0 | U22: 0/0 | AB22: Apri | AC22: Apri | AD22: Apri
A23: TERZA FASCIA | B23: 64.6 | C23: FALSE | E23: Stankovic F. | F23: Venezia | G23: 11 | H23: Titolare fisso | I23: Titolare fisso · Novità / ritorno in A | J23: 24 | K23: Serbia | L23: Dx | P23: 2 | Q23: 6 | R23: 4 | S23: 0 | T23: 0 | U23: 0/0 | AB23: Apri | AC23: Apri | AD23: Apri
A24: TERZA FASCIA | B24: 62.5 | C24: FALSE | E24: Paleari A. | F24: Torino | G24: 17 | H24: Rotazione / riserva | I24: Rotazione / riserva | J24: 34 | K24: Italia | L24: Dx | P24: 0 | Q24: 0 | R24: 0 | S24: 0 | T24: 0 | U24: 0/0 | V24: 29 | W24: 6.12 | X24: 4.55 | Y24: 0 | Z24: 0 | AA24: 0/0 | AB24: Apri | AC24: Apri | AD24: Apri
A25: TERZA FASCIA | B25: 52.2 | C25: FALSE | E25: Thiam D. | F25: Monza | G25: 7 | H25: Ballottaggio (Tornqvist N.) | I25: Ballottaggio (Tornqvist N.) · Novità / ritorno in A | J25: 28 | K25: Senegal | L25: Dx | P25: 1 | Q25: 4.5 | R25: 1.5 | S25: 0 | T25: 0 | U25: 0/0 | AB25: Apri | AC25: Apri | AD25: Apri
A26: TERZA FASCIA | B26: 36.1 | C26: FALSE | D26: ★ | E26: Daffara G. | F26: Parma | G26: 1 | H26: Titolare probabile | I26: Titolare probabile · Under 23 | J26: 21 | K26: Italia | L26: Dx | P26: 0 | Q26: 0 | R26: 0 | S26: 0 | T26: 0 | U26: 0/0 | AB26: Apri | AC26: Apri | AD26: Apri
A27: TERZA FASCIA | B27: 36.1 | C27: FALSE | E27: Tornqvist N. | F27: Monza | G27: 1 | H27: Ballottaggio (Thiam D.) | I27: Ballottaggio (Thiam D.) | J27: 24 | K27: Svezia | L27: Sx | P27: 0 | Q27: 0 | R27: 0 | S27: 0 | T27: 0 | U27: 0/0 | V27: 0 | W27: 0 | X27: 0 | Y27: 0 | Z27: 0 | AA27: 0/0 | AB27: Apri | AC27: Apri | AD27: Apri
A28: TERZA FASCIA | B28: 32.7 | C28: FALSE | E28: Corvi E. | F28: Parma | G28: 1 | H28: Rotazione / riserva | I28: Rotazione / riserva | J28: 25 | K28: Italia | L28: Dx | P28: 2 | Q28: 6.25 | R28: 4.75 | S28: 0 | T28: 0 | U28: 0/0 | V28: 17 | W28: 6.24 | X28: 5.15 | Y28: 0 | Z28: 0 | AA28: 0/0 | AB28: Apri | AC28: Apri | AD28: Apri
A29: TERZA FASCIA | B29: 30.4 | C29: FALSE | E29: Montipo L. | F29: Venezia | G29: 1 | H29: Rotazione / riserva | I29: Rotazione / riserva · Garanzia voto | J29: 30 | K29: Italia | L29: Dx | P29: 0 | Q29: 0 | R29: 0 | S29: 0 | T29: 0 | U29: 0/0 | V29: 35 | W29: 6.14 | X29: 4.89 | Y29: 0 | Z29: 1 | AA29: 0/0 | AB29: Apri | AC29: Apri | AD29: Apri
A30: TERZA FASCIA | B30: 29.9 | C30: FALSE | E30: Provedel I. | F30: Inter | G30: 1 | H30: Rotazione / riserva | I30: Rotazione / riserva | J30: 32 | K30: Italia | L30: Dx | P30: 0 | Q30: 0 | R30: 0 | S30: 0 | T30: 0 | U30: 0/0 | V30: 27 | W30: 6.28 | X30: 5.37 | Y30: 0 | Z30: 0 | AA30: 0/0 | AB30: Apri | AC30: Apri | AD30: Apri
A31: TERZA FASCIA | B31: 29.6 | C31: FALSE | E31: Mazzocchi A. | F31: Parma | G31: 1 | H31: Rotazione / riserva | I31: Rotazione / riserva · Under 23 | J31: 18 | K31: Italien | V31: 9 | W31: 5.83 | X31: 5.83 | Y31: 0 | Z31: 1 | AA31: 0/0 | AB31: Apri | AD31: Apri
A32: TERZA FASCIA | B32: 29.4 | C32: FALSE | E32: Christensen O. | F32: Fiorentina | G32: 1 | H32: Rotazione / riserva | I32: Rotazione / riserva | J32: 27 | K32: Danimarca | L32: Dx | P32: 0 | Q32: 0 | R32: 0 | S32: 0 | T32: 0 | U32: 0/0 | V32: 1 | W32: 7.5 | X32: 6.5 | Y32: 0 | Z32: 0 | AA32: 0/0 | AB32: Apri | AC32: Apri | AD32: Apri
A33: TERZA FASCIA | B33: 29.2 | C33: FALSE | E33: Terracciano P. | F33: Milan | G33: 1 | H33: Rotazione / riserva | I33: Rotazione / riserva | J33: 36 | K33: Italia | L33: Dx | P33: 0 | Q33: 0 | R33: 0 | S33: 0 | T33: 0 | U33: 0/0 | V33: 2 | W33: 6 | X33: 6 | Y33: 0 | Z33: 0 | AA33: 0/0 | AB33: Apri | AC33: Apri | AD33: Apri
A34: TERZA FASCIA | B34: 29.1 | C34: FALSE | E34: Mascardi D. | F34: Torino | G34: 1 | H34: Rotazione / riserva | I34: Rotazione / riserva · Under 23 | J34: 19 | K34: Italia | L34: Dx | P34: 2 | Q34: 6 | R34: 4 | S34: 0 | T34: 0 | U34: 0/0 | AB34: Apri | AC34: Apri | AD34: Apri
A35: TERZA FASCIA | B35: 29 | C35: FALSE | E35: Motta E. | F35: Lazio | G35: 1 | H35: Rotazione / riserva | I35: Rotazione / riserva · Under 23 | J35: 21 | K35: Italia | L35: Dx | P35: 0 | Q35: 0 | R35: 0 | S35: 0 | T35: 0 | U35: 0/0 | V35: 9 | W35: 6 | X35: 5.17 | Y35: 0 | Z35: 0 | AA35: 0/0 | AB35: Apri | AC35: Apri | AD35: Apri
A36: TERZA FASCIA | B36: 28.9 | C36: FALSE | E36: Pessina M. | F36: Bologna | G36: 1 | H36: Rotazione / riserva | I36: Rotazione / riserva · Under 23 | J36: 18 | K36: Bologna | L36: Dx | P36: 0 | Q36: 0 | R36: 0 | S36: 0 | T36: 0 | U36: 0/0 | V36: 4 | W36: 6.12 | X36: 5.62 | Y36: 0 | Z36: 0 | AA36: 0/0 | AB36: Apri | AC36: Apri | AD36: Apri
A37: TERZA FASCIA | B37: 28.8 | C37: FALSE | E37: Turati S. | F37: Sassuolo | G37: 1 | H37: Rotazione / riserva | I37: Rotazione / riserva | J37: 25 | K37: Italia | L37: Dx | P37: 0 | Q37: 0 | R37: 0 | S37: 0 | T37: 0 | U37: 0/0 | V37: 6 | W37: 6.25 | X37: 5.08 | Y37: 0 | Z37: 0 | AA37: 0/0 | AB37: Apri | AC37: Apri | AD37: Apri
A38: TERZA FASCIA | B38: 28.6 | C38: FALSE | E38: Padelli D. | F38: Udinese | G38: 1 | H38: Rotazione / riserva | I38: Rotazione / riserva | J38: 40 | K38: Italia | L38: Dx | P38: 0 | Q38: 0 | R38: 0 | S38: 0 | T38: 0 | U38: 0/0 | V38: 2 | W38: 6.25 | X38: 5.25 | Y38: 0 | Z38: 0 | AA38: 0/0 | AB38: Apri | AC38: Apri | AD38: Apri
A39: TERZA FASCIA | B39: 28.5 | C39: FALSE | E39: Furlanetto A. | F39: Lazio | G39: 1 | H39: Rotazione / riserva | I39: Rotazione / riserva | J39: 24 | K39: Italien | V39: 2 | W39: 6.5 | X39: 5 | Y39: 0 | Z39: 0 | AA39: 0/0 | AB39: Apri | AD39: Apri
A40: TERZA FASCIA | B40: 28.5 | C40: FALSE | E40: Sommariva D. | F40: Genoa | G40: 1 | H40: Rotazione / riserva | I40: Rotazione / riserva | J40: 29 | K40: Italia | L40: Dx | P40: 0 | Q40: 0 | R40: 0 | S40: 0 | T40: 0 | U40: 0/0 | V40: 2 | W40: 5.75 | X40: 3.75 | Y40: 0 | Z40: 0 | AA40: 0/0 | AB40: Apri | AC40: Apri | AD40: Apri
A41: QUARTA FASCIA | B41: 28.3 | C41: FALSE | E41: Sportiello M. | F41: Atalanta | G41: 1 | H41: Rotazione / riserva | I41: Rotazione / riserva | J41: 34 | K41: Italia | L41: Dx | P41: 0 | Q41: 0 | R41: 0 | S41: 0 | T41: 0 | U41: 0/0 | V41: 1 | W41: 5.5 | X41: 4.5 | Y41: 0 | Z41: 0 | AA41: 0/0 | AB41: Apri | AC41: Apri | AD41: Apri
...

Sheet Portieri
A1: Portieri
A2: 72 portierei — quattro fasce e gerarchie d'asta
A4: Fascia | B4: Score asta | C4: ✓ | D4: Scommessa | E4: Nome | F4: Squadra attuale | G4: Quotazione Gazzetta | H4: Titolarità | I4: Tag | J4: Età | K4: Nazionalità | L4: Piede | M4: Rigorista | N4: Punizioni | O4: Stato fisico / rientro | P4: PG 26/27 | Q4: MV 26/27 | R4: FM 26/27 | S4: Gol 26/27 | T4: Assist 26/27 | U4: Rigori 26/27 | V4: PG 25/26 | W4: MV 25/26 | X4: FM 25/26 | Y4: Gol 25/26 | Z4: Assist 25/26 | AA4: Rigori 25/26 | AB4: Scheda Gazzetta | AC4: Scheda statistiche | AD4: Fonte gerarchie
A5: TOP | B5: 91.3 | C5: FALSE | E5: Svilar M. | F5: Roma | G5: 40 | H5: Titolare fisso | I5: Titolare fisso · Consigliato Gazzetta · Garanzia voto | J5: 27 | K5: Serbia, Belgio | L5: Dx | P5: 2 | Q5: 6.25 | R5: 6.25 | S5: 0 | T5: 0 | U5: 0/0 | V5: 38 | W5: 6.32 | X5: 5.5 | Y5: 0 | Z5: 0 | AA5: 0/0 | AB5: Apri | AC5: Apri | AD5: Apri
A6: TOP | B6: 90.4 | C6: FALSE | E6: Carnesecchi M. | F6: Atalanta | G6: 35 | H6: Titolare fisso | I6: Titolare fisso · Consigliato Gazzetta · Garanzia voto | J6: 26 | K6: Italia | L6: Dx | P6: 2 | Q6: 6.75 | R6: 6.75 | S6: 0 | T6: 1 | U6: 0/0 | V6: 37 | W6: 6.43 | X6: 5.65 | Y6: 0 | Z6: 0 | AA6: 0/0 | AB6: Apri | AC6: Apri | AD6: Apri
A7: TOP | B7: 85.3 | C7: FALSE | E7: Maignan M. | F7: Milan | G7: 34 | H7: Titolare fisso | I7: Titolare fisso · Garanzia voto | J7: 31 | K7: Francia, Guyana Francese | L7: Dx | P7: 2 | Q7: 6 | R7: 5.5 | S7: 0 | T7: 0 | U7: 0/0 | V7: 37 | W7: 6.3 | X7: 5.46 | Y7: 0 | Z7: 0 | AA7: 0/0 | AB7: Apri | AC7: Apri | AD7: Apri
A8: TOP | B8: 84 | C8: FALSE | E8: Martinez J. | F8: Inter | G8: 29 | H8: Titolare fisso | I8: Titolare fisso · Consigliato Gazzetta | J8: 28 | K8: Spagna | L8: Dx | P8: 2 | Q8: 6 | R8: 5.5 | S8: 0 | T8: 0 | U8: 0/0 | V8: 5 | W8: 6 | X8: 5.2 | Y8: 0 | Z8: 0 | AA8: 0/0 | AB8: Apri | AC8: Apri | AD8: Apri
A9: TOP | B9: 83.7 | C9: FALSE | E9: Vicario G. | F9: Juventus | G9: 32 | H9: Titolare fisso | I9: Titolare fisso · Consigliato Gazzetta · Novità / ritorno in A | J9: 29 | K9: Italia | L9: Dx | P9: 2 | Q9: 6.5 | R9: 6.5 | S9: 0 | T9: 0 | U9: 0/0 | AB9: Apri | AC9: Apri | AD9: Apri
A10: TOP | B10: 83.7 | C10: FALSE | E10: Butez J. | F10: Como | G10: 31 | H10: Titolare fisso | I10: Titolare fisso · Garanzia voto | J10: 31 | K10: Francia | L10: Dx | P10: 3 | Q10: 6.17 | R10: 5.17 | S10: 0 | T10: 0 | U10: 0/0 | V10: 38 | W10: 6.11 | X10: 5.41 | Y10: 0 | Z10: 1 | AA10: 0/0 | AB10: Apri | AC10: Apri | AD10: Apri
A11: TOP | B11: 78.2 | C11: FALSE | E11: Skorupski L. | F11: Bologna | G11: 22 | H11: Titolare fisso | I11: Titolare fisso | J11: 35 | K11: Polonia | L11: Dx | P11: 2 | Q11: 5.25 | R11: 4.25 | S11: 0 | T11: 0 | U11: 0/0 | V11: 18 | W11: 6.14 | X11: 5.22 | Y11: 0 | Z11: 0 | AA11: 0/0 | AB11: Apri | AC11: Apri | AD11: Apri
A12: TOP | B12: 77.5 | C12: FALSE | E12: Caprile E. | F12: Cagliari | G12: 21 | H12: Titolare fisso | I12: Titolare fisso · Garanzia voto | J12: 25 | K12: Italia | L12: Dx | P12: 2 | Q12: 6.5 | R12: 6 | S12: 0 | T12: 0 | U12: 0/0 | V12: 38 | W12: 6.29 | X12: 4.87 | Y12: 0 | Z12: 0 | AA12: 0/0 | AB12: Apri | AC12: Apri | AD12: Apri
A13: SEMITOP | B13: 77.4 | C13: FALSE | E13: Mandas C. | F13: Lazio | G13: 29 | H13: Titolare fisso | I13: Titolare fisso · Novità / ritorno in A | J13: 24 | K13: Grecia | L13: Dx | P13: 2 | Q13: 6.5 | R13: 6.5 | S13: 0 | T13: 0 | U13: 0/0 | V13: 0 | W13: 0 | X13: 0 | Y13: 0 | Z13: 0 | AA13: 0/0 | AB13: Apri | AC13: Apri | AD13: Apri
A14: SEMITOP | B14: 75.1 | C14: FALSE | E14: Meret A. | F14: Napoli | G14: 15 | H14: Titolare fisso | I14: Titolare fisso · Consigliato Gazzetta | J14: 29 | K14: Italia | L14: Sx | P14: 2 | Q14: 6 | R14: 5 | S14: 0 | T14: 0 | U14: 0/0 | V14: 11 | W14: 6.18 | X14: 5.14 | Y14: 0 | Z14: 1 | AA14: 0/0 | AB14: Apri | AC14: Apri | AD14: Apri
A15: SEMITOP | B15: 75.1 | C15: FALSE | E15: Bijlow J. | F15: Genoa | G15: 17 | H15: Titolare fisso | I15: Titolare fisso | J15: 28 | K15: Olanda | L15: Dx | P15: 3 | Q15: 5.33 | R15: 3 | S15: 0 | T15: 0 | U15: 0/0 | V15: 16 | W15: 6.09 | X15: 4.81 | Y15: 0 | Z15: 0 | AA15: 0/0 | AB15: Apri | AC15: Apri | AD15: Apri
A16: SEMITOP | B16: 74.3 | C16: FALSE | E16: Okoye M. | F16: Udinese | G16: 16 | H16: Titolare fisso | I16: Titolare fisso · Garanzia voto | J16: 27 | K16: Nigeria, Germania | L16: Dx | P16: 2 | Q16: 6.25 | R16: 4.75 | S16: 0 | T16: 0 | U16: 0/0 | V16: 30 | W16: 6.08 | X16: 5.1 | Y16: 0 | Z16: 1 | AA16: 0/0 | AB16: Apri | AC16: Apri | AD16: Apri
A17: SEMITOP | B17: 73.5 | C17: FALSE | D17: ★★ | E17: Perri L. | F17: Torino | G17: 22 | H17: Titolare probabile | I17: Titolare probabile · Scommessa Gazzetta · Novità / ritorno in A | J17: 28 | K17: Brasile, Italia | L17: Dx | P17: 0 | Q17: 0 | R17: 0 | S17: 0 | T17: 0 | U17: 0/0 | AB17: Apri | AC17: Apri | AD17: Apri
A18: SEMITOP | B18: 72.5 | C18: FALSE | E18: Falcone W. | F18: Lecce | G18: 15 | H18: Titolare fisso | I18: Titolare fisso · Garanzia voto | J18: 31 | K18: Italia | L18: Dx | P18: 2 | Q18: 6.25 | R18: 4.25 | S18: 0 | T18: 0 | U18: 0/0 | V18: 38 | W18: 6.45 | X18: 5.26 | Y18: 0 | Z18: 0 | AA18: 0/0 | AB18: Apri | AC18: Apri | AD18: Apri
A19: SEMITOP | B19: 72.3 | C19: FALSE | E19: De Gea D. | F19: Fiorentina | G19: 15 | H19: Titolare fisso | I19: Titolare fisso · Garanzia voto | J19: 35 | K19: Spagna | L19: Dx | P19: 2 | Q19: 5 | R19: 1.5 | S19: 0 | T19: 0 | U19: 0/0 | V19: 37 | W19: 6.22 | X19: 4.97 | Y19: 0 | Z19: 0 | AA19: 0/0 | AB19: Apri | AC19: Apri | AD19: Apri
A20: SEMITOP | B20: 72.1 | C20: FALSE | E20: Muric A. | F20: Sassuolo | G20: 15 | H20: Titolare fisso | I20: Titolare fisso · Garanzia voto | J20: 27 | K20: Kosovo, Montenegro | L20: Dx | P20: 2 | Q20: 6.5 | R20: 5 | S20: 0 | T20: 0 | U20: 0/0 | V20: 32 | W20: 6.06 | X20: 4.75 | Y20: 0 | Z20: 0 | AA20: 0/0 | AB20: Apri | AC20: Apri | AD20: Apri
A21: SEMITOP | B21: 70.9 | C21: FALSE | E21: Milinkovic Savic V. | F21: Napoli | G21: 28 | H21: Rotazione / riserva | I21: Rotazione / riserva · Consigliato Gazzetta | J21: 29 | K21: Serbia, Spagna | L21: Dx | P21: 0 | Q21: 0 | R21: 0 | S21: 0 | T21: 0 | U21: 0/0 | V21: 27 | W21: 6.17 | X21: 5.61 | Y21: 0 | Z21: 0 | AA21: 0/0 | AB21: Apri | AC21: Apri | AD21: Apri
A22: SEMITOP | B22: 67.6 | C22: FALSE | D22: ★★★ | E22: Palmisani L. | F22: Frosinone | G22: 14 | H22: Titolare fisso | I22: Titolare fisso · Scommessa Gazzetta · Under 23 · Novità / ritorno in A | J22: 22 | K22: Italia | L22: Dx | P22: 2 | Q22: 6.25 | R22: 5.75 | S22: 0 | T22: 0 | U22: 0/0 | AB22: Apri | AC22: Apri | AD22: Apri
A23: TERZA FASCIA | B23: 64.6 | C23: FALSE | E23: Stankovic F. | F23: Venezia | G23: 11 | H23: Titolare fisso | I23: Titolare fisso · Novità / ritorno in A | J23: 24 | K23: Serbia | L23: Dx | P23: 2 | Q23: 6 | R23: 4 | S23: 0 | T23: 0 | U23: 0/0 | AB23: Apri | AC23: Apri | AD23: Apri
A24: TERZA FASCIA | B24: 62.5 | C24: FALSE | E24: Paleari A. | F24: Torino | G24: 17 | H24: Rotazione / riserva | I24: Rotazione / riserva | J24: 34 | K24: Italia | L24: Dx | P24: 0 | Q24: 0 | R24: 0 | S24: 0 | T24: 0 | U24: 0/0 | V24: 29 | W24: 6.12 | X24: 4.55 | Y24: 0 | Z24: 0 | AA24: 0/0 | AB24: Apri | AC24: Apri | AD24: Apri
A25: TERZA FASCIA | B25: 52.2 | C25: FALSE | E25: Thiam D. | F25: Monza | G25: 7 | H25: Ballottaggio (Tornqvist N.) | I25: Ballottaggio (Tornqvist N.) · Novità / ritorno in A | J25: 28 | K25: Senegal | L25: Dx | P25: 1 | Q25: 4.5 | R25: 1.5 | S25: 0 | T25: 0 | U25: 0/0 | AB25: Apri | AC25: Apri | AD25: Apri
A26: TERZA FASCIA | B26: 36.1 | C26: FALSE | D26: ★ | E26: Daffara G. | F26: Parma | G26: 1 | H26: Titolare probabile | I26: Titolare probabile · Under 23 | J26: 21 | K26: Italia | L26: Dx | P26: 0 | Q26: 0 | R26: 0 | S26: 0 | T26: 0 | U26: 0/0 | AB26: Apri | AC26: Apri | AD26: Apri
A27: TERZA FASCIA | B27: 36.1 | C27: FALSE | E27: Tornqvist N. | F27: Monza | G27: 1 | H27: Ballottaggio (Thiam D.) | I27: Ballottaggio (Thiam D.) | J27: 24 | K27: Svezia | L27: Sx | P27: 0 | Q27: 0 | R27: 0 | S27: 0 | T27: 0 | U27: 0/0 | V27: 0 | W27: 0 | X27: 0 | Y27: 0 | Z27: 0 | AA27: 0/0 | AB27: Apri | AC27: Apri | AD27: Apri
A28: TERZA FASCIA | B28: 32.7 | C28: FALSE | E28: Corvi E. | F28: Parma | G28: 1 | H28: Rotazione / riserva | I28: Rotazione / riserva | J28: 25 | K28: Italia | L28: Dx | P28: 2 | Q28: 6.25 | R28: 4.75 | S28: 0 | T28: 0 | U28: 0/0 | V28: 17 | W28: 6.24 | X28: 5.15 | Y28: 0 | Z28: 0 | AA28: 0/0 | AB28: Apri | AC28: Apri | AD28: Apri
A29: TERZA FASCIA | B29: 30.4 | C29: FALSE | E29: Montipo L. | F29: Venezia | G29: 1 | H29: Rotazione / riserva | I29: Rotazione / riserva · Garanzia voto | J29: 30 | K29: Italia | L29: Dx | P29: 0 | Q29: 0 | R29: 0 | S29: 0 | T29: 0 | U29: 0/0 | V29: 35 | W29: 6.14 | X29: 4.89 | Y29: 0 | Z29: 1 | AA29: 0/0 | AB29: Apri | AC29: Apri | AD29: Apri
A30: TERZA FASCIA | B30: 29.9 | C30: FALSE | E30: Provedel I. | F30: Inter | G30: 1 | H30: Rotazione / riserva | I30: Rotazione / riserva | J30: 32 | K30: Italia | L30: Dx | P30: 0 | Q30: 0 | R30: 0 | S30: 0 | T30: 0 | U30: 0/0 | V30: 27 | W30: 6.28 | X30: 5.37 | Y30: 0 | Z30: 0 | AA30: 0/0 | AB30: Apri | AC30: Apri | AD30: Apri
A31: TERZA FASCIA | B31: 29.6 | C31: FALSE | E31: Mazzocchi A. | F31: Parma | G31: 1 | H31: Rotazione / riserva | I31: Rotazione / riserva · Under 23 | J31: 18 | K31: Italien | V31: 9 | W31: 5.83 | X31: 5.83 | Y31: 0 | Z31: 1 | AA31: 0/0 | AB31: Apri | AD31: Apri
A32: TERZA FASCIA | B32: 29.4 | C32: FALSE | E32: Christensen O. | F32: Fiorentina | G32: 1 | H32: Rotazione / riserva | I32: Rotazione / riserva | J32: 27 | K32: Danimarca | L32: Dx | P32: 0 | Q32: 0 | R32: 0 | S32: 0 | T32: 0 | U32: 0/0 | V32: 1 | W32: 7.5 | X32: 6.5 | Y32: 0 | Z32: 0 | AA32: 0/0 | AB32: Apri | AC32: Apri | AD32: Apri
A33: TERZA FASCIA | B33: 29.2 | C33: FALSE | E33: Terracciano P. | F33: Milan | G33: 1 | H33: Rotazione / riserva | I33: Rotazione / riserva | J33: 36 | K33: Italia | L33: Dx | P33: 0 | Q33: 0 | R33: 0 | S33: 0 | T33: 0 | U33: 0/0 | V33: 2 | W33: 6 | X33: 6 | Y33: 0 | Z33: 0 | AA33: 0/0 | AB33: Apri | AC33: Apri | AD33: Apri
A34: TERZA FASCIA | B34: 29.1 | C34: FALSE | E34: Mascardi D. | F34: Torino | G34: 1 | H34: Rotazione / riserva | I34: Rotazione / riserva · Under 23 | J34: 19 | K34: Italia | L34: Dx | P34: 2 | Q34: 6 | R34: 4 | S34: 0 | T34: 0 | U34: 0/0 | AB34: Apri | AC34: Apri | AD34: Apri
A35: TERZA FASCIA | B35: 29 | C35: FALSE | E35: Motta E. | F35: Lazio | G35: 1 | H35: Rotazione / riserva | I35: Rotazione / riserva · Under 23 | J35: 21 | K35: Italia | L35: Dx | P35: 0 | Q35: 0 | R35: 0 | S35: 0 | T35: 0 | U35: 0/0 | V35: 9 | W35: 6 | X35: 5.17 | Y35: 0 | Z35: 0 | AA35: 0/0 | AB35: Apri | AC35: Apri | AD35: Apri
A36: TERZA FASCIA | B36: 28.9 | C36: FALSE | E36: Pessina M. | F36: Bologna | G36: 1 | H36: Rotazione / riserva | I36: Rotazione / riserva · Under 23 | J36: 18 | K36: Bologna | L36: Dx | P36: 0 | Q36: 0 | R36: 0 | S36: 0 | T36: 0 | U36: 0/0 | V36: 4 | W36: 6.12 | X36: 5.62 | Y36: 0 | Z36: 0 | AA36: 0/0 | AB36: Apri | AC36: Apri | AD36: Apri
A37: TERZA FASCIA | B37: 28.8 | C37: FALSE | E37: Turati S. | F37: Sassuolo | G37: 1 | H37: Rotazione / riserva | I37: Rotazione / riserva | J37: 25 | K37: Italia | L37: Dx | P37: 0 | Q37: 0 | R37: 0 | S37: 0 | T37: 0 | U37: 0/0 | V37: 6 | W37: 6.25 | X37: 5.08 | Y37: 0 | Z37: 0 | AA37: 0/0 | AB37: Apri | AC37: Apri | AD37: Apri
A38: TERZA FASCIA | B38: 28.6 | C38: FALSE | E38: Padelli D. | F38: Udinese | G38: 1 | H38: Rotazione / riserva | I38: Rotazione / riserva | J38: 40 | K38: Italia | L38: Dx | P38: 0 | Q38: 0 | R38: 0 | S38: 0 | T38: 0 | U38: 0/0 | V38: 2 | W38: 6.25 | X38: 5.25 | Y38: 0 | Z38: 0 | AA38: 0/0 | AB38: Apri | AC38: Apri | AD38: Apri
A39: TERZA FASCIA | B39: 28.5 | C39: FALSE | E39: Furlanetto A. | F39: Lazio | G39: 1 | H39: Rotazione / riserva | I39: Rotazione / riserva | J39: 24 | K39: Italien | V39: 2 | W39: 6.5 | X39: 5 | Y39: 0 | Z39: 0 | AA39: 0/0 | AB39: Apri | AD39: Apri
A40: TERZA FASCIA | B40: 28.5 | C40: FALSE | E40: Sommariva D. | F40: Genoa | G40: 1 | H40: Rotazione / riserva | I40: Rotazione / riserva | J40: 29 | K40: Italia | L40: Dx | P40: 0 | Q40: 0 | R40: 0 | S40: 0 | T40: 0 | U40: 0/0 | V40: 2 | W40: 5.75 | X40: 3.75 | Y40: 0 | Z40: 0 | AA40: 0/0 | AB40: Apri | AC40: Apri | AD40: Apri
A41: QUARTA FASCIA | B41: 28.3 | C41: FALSE | E41: Sportiello M. | F41: Atalanta | G41: 1 | H41: Rotazione / riserva | I41: Rotazione / riserva | J41: 34 | K41: Italia | L41: Dx | P41: 0 | Q41: 0 | R41: 0 | S41: 0 | T41: 0 | U41: 0/0 | V41: 1 | W41: 5.5 | X41: 4.5 | Y41: 0 | Z41: 0 | AA41: 0/0 | AB41: Apri | AC41: Apri | AD41: Apri
...

Sheet Difensori
A1: Difensori
A2: 199 difensorei — quattro fasce e gerarchie d'asta
A4: Fascia | B4: Score asta | C4: ✓ | D4: Scommessa | E4: Nome | F4: Squadra attuale | G4: Quotazione Gazzetta | H4: Titolarità | I4: Tag | J4: Età | K4: Nazionalità | L4: Piede | M4: Rigorista | N4: Punizioni | O4: Stato fisico / rientro | P4: PG 26/27 | Q4: MV 26/27 | R4: FM 26/27 | S4: Gol 26/27 | T4: Assist 26/27 | U4: Rigori 26/27 | V4: PG 25/26 | W4: MV 25/26 | X4: FM 25/26 | Y4: Gol 25/26 | Z4: Assist 25/26 | AA4: Rigori 25/26 | AB4: Scheda Gazzetta | AC4: Scheda statistiche | AD4: Fonte gerarchie
A5: TOP | B5: 92.8 | C5: FALSE | E5: Dimarco F. | F5: Inter | G5: 42 | H5: Ballottaggio (Carlos Augusto) | I5: Ballottaggio (Carlos Augusto) · Calci piazzati · Consigliato Gazzetta · Garanzia voto · Portatore di bonus | J5: 28 | K5: Italia | L5: Sx | N5: 2° | P5: 2 | Q5: 6.25 | R5: 6.25 | S5: 0 | T5: 0 | U5: 0/0 | V5: 35 | W5: 6.64 | X5: 7.69 | Y5: 7 | Z5: 17 | AA5: 0/0 | AB5: Apri | AC5: Apri | AD5: Apri
A6: TOP | B6: 92.8 | C6: FALSE | D6: ★★ | E6: Mancini G. | F6: Roma | G6: 36 | H6: Titolare fisso | I6: Titolare fisso · Consigliato Gazzetta · Scommessa Gazzetta · Garanzia voto · Portatore di bonus | J6: 30 | K6: Italia | L6: Dx | P6: 2 | Q6: 6.5 | R6: 7 | S6: 0 | T6: 1 | U6: 0/0 | V6: 36 | W6: 6.31 | X6: 6.57 | Y6: 4 | Z6: 2 | AA6: 0/0 | AB6: Apri | AC6: Apri | AD6: Apri
A7: TOP | B7: 91.1 | C7: FALSE | E7: Bremer | F7: Juventus | G7: 37 | H7: Titolare fisso | I7: Titolare fisso · Consigliato Gazzetta · Portatore di bonus | J7: 29 | K7: Brasile | L7: Dx | P7: 2 | Q7: 6.75 | R7: 8.25 | S7: 1 | T7: 0 | U7: 0/0 | V7: 26 | W7: 6.29 | X7: 6.77 | Y7: 4 | Z7: 3 | AA7: 0/0 | AB7: Apri | AC7: Apri | AD7: Apri
A8: TOP | B8: 91 | C8: FALSE | E8: Wesley | F8: Roma | G8: 37 | H8: Titolare fisso | I8: Titolare fisso · Consigliato Gazzetta · Under 23 · Garanzia voto · Portatore di bonus | J8: 22 | K8: Brasile | L8: Dx | P8: 2 | Q8: 6.75 | R8: 7.25 | S8: 0 | T8: 1 | U8: 0/0 | V8: 30 | W8: 6.17 | X8: 6.52 | Y8: 5 | Z8: 0 | AA8: 0/0 | AB8: Apri | AC8: Apri | AD8: Apri
A9: TOP | B9: 89.5 | C9: FALSE | E9: Bastoni A. | F9: Inter | G9: 34 | H9: Titolare fisso | I9: Titolare fisso · Consigliato Gazzetta · Portatore di bonus | J9: 27 | K9: Italia | L9: Sx | P9: 2 | Q9: 6 | R9: 6 | S9: 0 | T9: 0 | U9: 0/0 | V9: 28 | W9: 6.16 | X9: 6.3 | Y9: 1 | Z9: 4 | AA9: 0/0 | AB9: Apri | AC9: Apri | AD9: Apri
A10: TOP | B10: 89.2 | C10: FALSE | E10: Zappacosta D. | F10: Atalanta | G10: 32 | H10: Titolare fisso | I10: Titolare fisso · Consigliato Gazzetta · Garanzia voto | J10: 34 | K10: Italia | L10: Dx | P10: 2 | Q10: 6.25 | R10: 6.25 | S10: 0 | T10: 0 | U10: 0/0 | V10: 35 | W10: 6.03 | X10: 6.27 | Y10: 3 | Z10: 1 | AA10: 0/0 | AB10: Apri | AC10: Apri | AD10: Apri
A11: TOP | B11: 88.6 | C11: FALSE | D11: ★★ | E11: Ndicka E. | F11: Roma | G11: 31 | H11: Ballottaggio (Ghilardi D.) | I11: Ballottaggio (Ghilardi D.) · Consigliato Gazzetta · Scommessa Gazzetta · Garanzia voto | J11: 27 | K11: Francia, Camerun | L11: Sx | P11: 1 | Q11: 6.5 | R11: 6.5 | S11: 0 | T11: 0 | U11: 0/0 | V11: 31 | W11: 6.15 | X11: 6.39 | Y11: 3 | Z11: 1 | AA11: 0/0 | AB11: Apri | AC11: Apri | AD11: Apri
A12: TOP | B12: 88.5 | C12: FALSE | E12: Kalulu P. | F12: Juventus | G12: 31 | H12: Titolare fisso | I12: Titolare fisso · Consigliato Gazzetta · Garanzia voto · Portatore di bonus | J12: 26 | K12: Francia, Repubblica Democratica del Congo | L12: Dx | P12: 2 | Q12: 6.5 | R12: 6.5 | S12: 0 | T12: 0 | U12: 0/0 | V12: 37 | W12: 6.2 | X12: 6.42 | Y12: 2 | Z12: 4 | AA12: 0/0 | AB12: Apri | AC12: Apri | AD12: Apri
A13: TOP | B13: 88.4 | C13: FALSE | E13: Solet O. | F13: Udinese | G13: 31 | H13: Titolare fisso | I13: Titolare fisso · Consigliato Gazzetta · Garanzia voto | J13: 26 | K13: Francia, Repubblica Centrafricana | L13: Dx | P13: 2 | Q13: 6.25 | R13: 6.25 | S13: 0 | T13: 0 | U13: 0/0 | V13: 35 | W13: 6.26 | X13: 6.47 | Y13: 3 | Z13: 1 | AA13: 1/1 | AB13: Apri | AC13: Apri | AD13: Apri
A14: TOP | B14: 88.2 | C14: FALSE | D14: ★★ | E14: Pavlovic S. | F14: Milan | G14: 34 | H14: Titolare fisso | I14: Titolare fisso · Scommessa Gazzetta · Garanzia voto · Portatore di bonus | J14: 25 | K14: Serbia | L14: Sx | P14: 2 | Q14: 6.5 | R14: 6.25 | S14: 0 | T14: 0 | U14: 0/0 | V14: 34 | W14: 6.28 | X14: 6.66 | Y14: 5 | Z14: 0 | AA14: 0/0 | AB14: Apri | AC14: Apri | AD14: Apri
A15: TOP | B15: 87.3 | C15: FALSE | E15: Di Lorenzo G. | F15: Napoli | G15: 31 | H15: Titolare fisso | I15: Titolare fisso · Consigliato Gazzetta | J15: 33 | K15: Italia | L15: Dx | P15: 2 | Q15: 6 | R15: 5.75 | S15: 0 | T15: 0 | U15: 0/0 | V15: 26 | W15: 6.02 | X15: 6.27 | Y15: 2 | Z15: 1 | AA15: 0/0 | AB15: Apri | AC15: Apri | AD15: Apri
A16: TOP | B16: 86.9 | C16: FALSE | E16: Akanji M. | F16: Inter | G16: 30 | H16: Ballottaggio (Stones J.) | I16: Ballottaggio (Stones J.) · Consigliato Gazzetta · Garanzia voto | J16: 31 | K16: Svizzera, Nigeria | L16: Dx | P16: 2 | Q16: 5.5 | R16: 5.25 | S16: 0 | T16: 0 | U16: 0/0 | V16: 32 | W16: 6.27 | X16: 6.39 | Y16: 2 | Z16: 0 | AA16: 0/0 | AB16: Apri | AC16: Apri | AD16: Apri
A17: TOP | B17: 85.1 | C17: FALSE | D17: ★★ | E17: Hermoso M. | F17: Roma | G17: 25 | H17: Titolare fisso | I17: Titolare fisso · Consigliato Gazzetta · Scommessa Gazzetta · Portatore di bonus | J17: 31 | K17: Spagna | L17: Sx | P17: 2 | Q17: 6.5 | R17: 6.25 | S17: 0 | T17: 0 | U17: 0/0 | V17: 27 | W17: 6.17 | X17: 6.41 | Y17: 3 | Z17: 2 | AA17: 0/0 | AB17: Apri | AC17: Apri | AD17: Apri
A18: TOP | B18: 81.8 | C18: FALSE | E18: Stones J. | F18: Inter | G18: 30 | H18: Ballottaggio (Akanji M.) | I18: Ballottaggio (Akanji M.) · Consigliato Gazzetta · Novità / ritorno in A | J18: 32 | K18: Inghilterra | L18: Dx | P18: 2 | Q18: 6 | R18: 6 | S18: 0 | T18: 0 | U18: 0/0 | AB18: Apri | AC18: Apri | AD18: Apri
A19: TOP | B19: 81.5 | C19: FALSE | E19: Spinazzola L. | F19: Napoli | G19: 27 | H19: Titolare fisso | I19: Titolare fisso · Garanzia voto · Portatore di bonus | J19: 33 | K19: Italia | L19: Dx | P19: 2 | Q19: 5.75 | R19: 5.75 | S19: 0 | T19: 0 | U19: 0/0 | V19: 30 | W19: 6.1 | X19: 6.48 | Y19: 3 | Z19: 3 | AA19: 0/0 | AB19: Apri | AC19: Apri | AD19: Apri
A20: TOP | B20: 80.7 | C20: FALSE | E20: Scalvini G. | F20: Atalanta | G20: 27 | H20: Titolare fisso | I20: Titolare fisso · Under 23 | J20: 22 | K20: Italia | L20: Dx | P20: 2 | Q20: 6 | R20: 6 | S20: 0 | T20: 0 | U20: 0/0 | V20: 24 | W20: 6.04 | X20: 6.42 | Y20: 3 | Z20: 1 | AA20: 0/0 | AB20: Apri | AC20: Apri | AD20: Apri
A21: TOP | B21: 80.2 | C21: FALSE | E21: Cambiaso A. | F21: Juventus | G21: 27 | H21: Titolare probabile | I21: Titolare probabile · Calci piazzati · Consigliato Gazzetta · Portatore di bonus · Rischio infortunio · Indisponibile ora | J21: 26 | K21: Italia | L21: Sx | N21: 3° | O21: Da valutare | P21: 1 | Q21: 5.5 | R21: 5 | S21: 0 | T21: 0 | U21: 0/0 | V21: 36 | W21: 5.79 | X21: 5.97 | Y21: 3 | Z21: 4 | AA21: 0/0 | AB21: Apri | AC21: Apri | AD21: Apri
A22: TOP | B22: 79.8 | C22: FALSE | E22: Ostigard L. | F22: Genoa | G22: 22 | H22: Titolare fisso | I22: Titolare fisso · Consigliato Gazzetta · Garanzia voto · Portatore di bonus | J22: 26 | K22: Norvegia | L22: Dx | P22: 3 | Q22: 5.67 | R22: 5.17 | S22: 0 | T22: 0 | U22: 0/0 | V22: 30 | W22: 6.13 | X22: 6.52 | Y22: 5 | Z22: 0 | AA22: 0/0 | AB22: Apri | AC22: Apri | AD22: Apri
A23: TOP | B23: 79.8 | C23: FALSE | E23: Molina N. | F23: Roma | G23: 29 | H23: Titolare probabile | I23: Titolare probabile · Consigliato Gazzetta · Novità / ritorno in A | J23: 28 | K23: Argentina | L23: Dx | P23: 1 | Q23: 6 | R23: 6 | S23: 0 | T23: 0 | U23: 0/0 | AB23: Apri | AC23: Apri | AD23: Apri
A24: TOP | B24: 79.2 | C24: FALSE | E24: Gila M. | F24: Milan | G24: 23 | H24: Titolare fisso | I24: Titolare fisso · Consigliato Gazzetta · Garanzia voto | J24: 26 | K24: Spagna | L24: Dx | P24: 2 | Q24: 6.5 | R24: 6.5 | S24: 0 | T24: 0 | U24: 0/0 | V24: 31 | W24: 5.95 | X24: 5.87 | Y24: 0 | Z24: 0 | AA24: 0/0 | AB24: Apri | AC24: Apri | AD24: Apri
A25: SEMITOP | B25: 78.7 | C25: FALSE | D25: ★★ | E25: Ramon J. | F25: Como | G25: 25 | H25: Titolare fisso | I25: Titolare fisso · Under 23 · Garanzia voto | J25: 21 | K25: Spagna | L25: Dx | P25: 3 | Q25: 6 | R25: 6 | S25: 0 | T25: 0 | U25: 0/0 | V25: 32 | W25: 6.16 | X25: 6.14 | Y25: 2 | Z25: 0 | AA25: 0/0 | AB25: Apri | AC25: Apri | AD25: Apri
A26: SEMITOP | B26: 78.5 | C26: FALSE | D26: ★★ | E26: Comuzzo P. | F26: Torino | G26: 23 | H26: Titolare fisso | I26: Titolare fisso · Consigliato Gazzetta · Under 23 | J26: 21 | K26: Italia | L26: Dx | P26: 2 | Q26: 6.25 | R26: 7.75 | S26: 1 | T26: 0 | U26: 0/0 | V26: 24 | W26: 5.73 | X26: 5.73 | Y26: 1 | Z26: 0 | AA26: 0/0 | AB26: Apri | AC26: Apri | AD26: Apri
A27: SEMITOP | B27: 78.5 | C27: FALSE | D27: ★★ | E27: Gabriel T. | F27: Lecce | G27: 21 | H27: Ballottaggio (Siebert J.) | I27: Ballottaggio (Siebert J.) · Consigliato Gazzetta · Under 23 · Garanzia voto | J27: 21 | K27: Portogallo | L27: Dx | P27: 2 | Q27: 6 | R27: 7.5 | S27: 1 | T27: 0 | U27: 0/0 | V27: 36 | W27: 6.03 | X27: 6.04 | Y27: 2 | Z27: 0 | AA27: 0/0 | AB27: Apri | AC27: Apri | AD27: Apri
A28: SEMITOP | B28: 77.9 | C28: FALSE | E28: Rrahmani A. | F28: Napoli | G28: 25 | H28: Titolare fisso | I28: Titolare fisso | J28: 32 | K28: Kosovo, Albania | L28: Ambidestro | P28: 2 | Q28: 6 | R28: 6.5 | S28: 0 | T28: 1 | U28: 0/0 | V28: 21 | W28: 6.26 | X28: 6.48 | Y28: 2 | Z28: 0 | AA28: 0/0 | AB28: Apri | AC28: Apri | AD28: Apri
A29: SEMITOP | B29: 77.5 | C29: FALSE | D29: ★★ | E29: Miranda J. | F29: Bologna | G29: 23 | H29: Titolare probabile | I29: Titolare probabile · Calci piazzati · Scommessa Gazzetta · Garanzia voto | J29: 26 | K29: Spagna | L29: Sx | N29: 3° | P29: 1 | Q29: 6 | R29: 6 | S29: 0 | T29: 0 | U29: 0/0 | V29: 31 | W29: 5.94 | X29: 6.03 | Y29: 1 | Z29: 3 | AA29: 0/0 | AB29: Apri | AC29: Apri | AD29: Apri
A30: SEMITOP | B30: 76.7 | C30: FALSE | E30: Valeri E. | F30: Parma | G30: 20 | H30: Titolare fisso | I30: Titolare fisso · Calci piazzati · Consigliato Gazzetta · Garanzia voto | J30: 27 | K30: Italia | L30: Sx | N30: 2° | P30: 2 | Q30: 5.75 | R30: 5.75 | S30: 0 | T30: 0 | U30: 0/0 | V30: 34 | W30: 6.1 | X30: 6.13 | Y30: 0 | Z30: 2 | AA30: 0/0 | AB30: Apri | AC30: Apri | AD30: Apri
A31: SEMITOP | B31: 76.3 | C31: FALSE | E31: Kamara H. | F31: Udinese | G31: 24 | H31: Titolare fisso | I31: Titolare fisso | J31: 32 | K31: Francia, Gambia | L31: Sx | P31: 2 | Q31: 7 | R31: 10 | S31: 2 | T31: 0 | U31: 0/0 | V31: 26 | W31: 5.9 | X31: 5.88 | Y31: 0 | Z31: 2 | AA31: 0/0 | AB31: Apri | AC31: Apri | AD31: Apri
A32: SEMITOP | B32: 76.1 | C32: FALSE | E32: Vasquez J. | F32: Genoa | G32: 20 | H32: Titolare fisso | I32: Titolare fisso · Consigliato Gazzetta · Garanzia voto | J32: 27 | K32: Messico | L32: Sx | P32: 3 | Q32: 5.33 | R32: 5.33 | S32: 0 | T32: 0 | U32: 0/0 | V32: 36 | W32: 6.11 | X32: 6.17 | Y32: 1 | Z32: 0 | AA32: 0/0 | AB32: Apri | AC32: Apri | AD32: Apri
A33: SEMITOP | B33: 76.1 | C33: FALSE | E33: Chalobah T. | F33: Como | G33: 27 | H33: Titolare fisso | I33: Titolare fisso · Novità / ritorno in A | J33: 27 | K33: Inghilterra, Sierra Leone | L33: Dx | P33: 3 | Q33: 6.33 | R33: 6.33 | S33: 0 | T33: 0 | U33: 0/0 | AB33: Apri | AC33: Apri | AD33: Apri
A34: SEMITOP | B34: 74.9 | C34: FALSE | E34: Bisseck Y. | F34: Inter | G34: 32 | H34: Ballottaggio (Pavard B.) | I34: Ballottaggio (Pavard B.) · Portatore di bonus | J34: 25 | K34: Germania, Camerun | L34: Dx | P34: 2 | Q34: 6.75 | R34: 8.25 | S34: 1 | T34: 0 | U34: 0/0 | V34: 23 | W34: 6.2 | X34: 6.63 | Y34: 3 | Z34: 2 | AA34: 0/0 | AB34: Apri | AC34: Apri | AD34: Apri
A35: SEMITOP | B35: 73.8 | C35: FALSE | D35: ★★ | E35: Spence D. | F35: Inter | G35: 26 | H35: Titolare probabile | I35: Titolare probabile · Scommessa Gazzetta · Novità / ritorno in A | J35: 26 | K35: Inghilterra, Giamaica | L35: Dx | P35: 0 | Q35: 0 | R35: 0 | S35: 0 | T35: 0 | U35: 0/0 | AB35: Apri | AC35: Apri | AD35: Apri
A36: SEMITOP | B36: 73 | C36: FALSE | E36: Holm E. | F36: Bologna | G36: 21 | H36: Titolare fisso | I36: Titolare fisso · Portatore di bonus | J36: 26 | K36: Svezia | L36: Dx | P36: 2 | Q36: 6 | R36: 6 | S36: 0 | T36: 0 | U36: 0/0 | V36: 16 | W36: 6.03 | X36: 6.38 | Y36: 1 | Z36: 4 | AA36: 0/0 | AB36: Apri | AC36: Apri | AD36: Apri
A37: SEMITOP | B37: 72.5 | C37: FALSE | E37: Dodo | F37: Fiorentina | G37: 26 | H37: Rotazione / riserva | I37: Rotazione / riserva · Consigliato Gazzetta · Garanzia voto | J37: 27 | K37: Brasile | L37: Dx | P37: 1 | Q37: 5 | R37: 5 | S37: 0 | T37: 0 | U37: 0/0 | V37: 36 | W37: 6.07 | X37: 6.11 | Y37: 1 | Z37: 2 | AA37: 0/0 | AB37: Apri | AC37: Apri | AD37: Apri
A38: SEMITOP | B38: 70.6 | C38: FALSE | E38: Gallo A. | F38: Lecce | G38: 20 | H38: Titolare probabile | I38: Titolare probabile · Garanzia voto | J38: 26 | K38: Italia | L38: Sx | P38: 1 | Q38: 5.5 | R38: 5.5 | S38: 0 | T38: 0 | U38: 0/0 | V38: 37 | W38: 5.93 | X38: 5.97 | Y38: 0 | Z38: 3 | AA38: 0/0 | AB38: Apri | AC38: Apri | AD38: Apri
A39: SEMITOP | B39: 70.5 | C39: FALSE | E39: Valle A. | F39: Como | G39: 27 | H39: Ballottaggio (Kaiki B.) | I39: Ballottaggio (Kaiki B.) · Under 23 | J39: 22 | K39: Spagna | L39: Sx | P39: 3 | Q39: 6.33 | R39: 6.67 | S39: 0 | T39: 1 | U39: 0/0 | V39: 26 | W39: 6.06 | X39: 6.23 | Y39: 1 | Z39: 3 | AA39: 0/0 | AB39: Apri | AC39: Apri | AD39: Apri
A40: SEMITOP | B40: 69.9 | C40: FALSE | E40: Kempf M. | F40: Como | G40: 27 | H40: Rotazione / riserva | I40: Rotazione / riserva · Garanzia voto · Portatore di bonus | J40: 31 | K40: Germania | L40: Sx | P40: 1 | Q40: 6.5 | R40: 6.5 | S40: 0 | T40: 0 | U40: 0/0 | V40: 30 | W40: 6.12 | X40: 6.5 | Y40: 4 | Z40: 1 | AA40: 0/0 | AB40: Apri | AC40: Apri | AD40: Apri
A41: SEMITOP | B41: 69.4 | C41: FALSE | E41: Delprato E. | F41: Parma | G41: 18 | H41: Titolare fisso | I41: Titolare fisso · Consigliato Gazzetta · Garanzia voto | J41: 26 | K41: Italia | L41: Dx | P41: 2 | Q41: 6 | R41: 5.75 | S41: 0 | T41: 0 | U41: 0/0 | V41: 35 | W41: 6.01 | X41: 6.11 | Y41: 2 | Z41: 0 | AA41: 0/0 | AB41: Apri | AC41: Apri | AD41: Apri
...

Sheet Centrocampisti
A1: Centrocampisti
A2: 199 centrocampistai — quattro fasce e gerarchie d'asta
A4: Fascia | B4: Score asta | C4: ✓ | D4: Scommessa | E4: Nome | F4: Squadra attuale | G4: Quotazione Gazzetta | H4: Titolarità | I4: Tag | J4: Età | K4: Nazionalità | L4: Piede | M4: Rigorista | N4: Punizioni | O4: Stato fisico / rientro | P4: PG 26/27 | Q4: MV 26/27 | R4: FM 26/27 | S4: Gol 26/27 | T4: Assist 26/27 | U4: Rigori 26/27 | V4: PG 25/26 | W4: MV 25/26 | X4: FM 25/26 | Y4: Gol 25/26 | Z4: Assist 25/26 | AA4: Rigori 25/26 | AB4: Scheda Gazzetta | AC4: Scheda statistiche | AD4: Fonte gerarchie
A5: TOP | B5: 95.6 | C5: FALSE | D5: ★★ | E5: Calhanoglu H. | F5: Inter | G5: 65 | H5: Ballottaggio (Sucic P.) | I5: Ballottaggio (Sucic P.) · Calci piazzati · Consigliato Gazzetta · Scommessa Gazzetta · Portatore di bonus | J5: 32 | K5: Turchia, Germania | L5: Dx | N5: 1° | P5: 2 | Q5: 7 | R5: 9.75 | S5: 2 | T5: 0 | U5: 0/0 | V5: 22 | W5: 6.43 | X5: 7.55 | Y5: 9 | Z5: 4 | AA5: 4/5 | AB5: Apri | AC5: Apri | AD5: Apri
A6: TOP | B6: 93.3 | C6: FALSE | E6: Paz N. | F6: Como | G6: 57 | H6: Titolare fisso | I6: Titolare fisso · Calci piazzati · Consigliato Gazzetta · Under 23 · Garanzia voto · Portatore di bonus | J6: 21 | K6: Argentina, Spagna | L6: Sx | N6: 1° | P6: 3 | Q6: 6.33 | R6: 7.33 | S6: 1 | T6: 0 | U6: 0/0 | V6: 35 | W6: 6.41 | X6: 7.34 | Y6: 12 | Z6: 5 | AA6: 0/2 | AB6: Apri | AC6: Apri | AD6: Apri
A7: TOP | B7: 91.9 | C7: FALSE | E7: Vlasic N. | F7: Torino | G7: 50 | H7: Titolare fisso | I7: Titolare fisso · Calci piazzati · Consigliato Gazzetta · Garanzia voto · Portatore di bonus | J7: 28 | K7: Croazia | L7: Dx | N7: 1° | P7: 2 | Q7: 5.5 | R7: 5.5 | S7: 0 | T7: 0 | U7: 0/0 | V7: 37 | W7: 6.07 | X7: 6.7 | Y7: 8 | Z7: 3 | AA7: 5/5 | AB7: Apri | AC7: Apri | AD7: Apri
A8: TOP | B8: 89.5 | C8: FALSE | E8: Rabiot A. | F8: Milan | G8: 50 | H8: Titolare fisso | I8: Titolare fisso · Consigliato Gazzetta · Portatore di bonus | J8: 31 | K8: Francia | L8: Sx | P8: 2 | Q8: 6.75 | R8: 8.75 | S8: 1 | T8: 1 | U8: 0/0 | V8: 29 | W8: 6.33 | X8: 6.98 | Y8: 6 | Z8: 4 | AA8: 0/0 | AB8: Apri | AC8: Apri | AD8: Apri
A9: TOP | B9: 89.2 | C9: FALSE | E9: Baturina M. | F9: Como | G9: 47 | H9: Titolare fisso | I9: Titolare fisso · Calci piazzati · Consigliato Gazzetta · Portatore di bonus | J9: 23 | K9: Croazia | L9: Dx | N9: 3° | P9: 3 | Q9: 6.67 | R9: 8.5 | S9: 2 | T9: 0 | U9: 0/0 | V9: 25 | W9: 6.34 | X9: 7.18 | Y9: 6 | Z9: 3 | AA9: 0/0 | AB9: Apri | AC9: Apri | AD9: Apri
A10: TOP | B10: 88.6 | C10: FALSE | E10: Pulisic C. | F10: Milan | G10: 55 | H10: Titolare probabile | I10: Titolare probabile · Calci piazzati · Consigliato Gazzetta · Portatore di bonus | J10: 27 | K10: Stati Uniti, Croazia | L10: Dx | N10: 2° | P10: 0 | Q10: 0 | R10: 0 | S10: 0 | T10: 0 | U10: 0/0 | V10: 29 | W10: 6.07 | X10: 6.93 | Y10: 8 | Z10: 4 | AA10: 0/1 | AB10: Apri | AC10: Apri | AD10: Apri
A11: TOP | B11: 87.3 | C11: FALSE | E11: Orsolini R. | F11: Bologna | G11: 51 | H11: Titolare probabile | I11: Titolare probabile · Calci piazzati · Consigliato Gazzetta · Garanzia voto · Portatore di bonus · Rischio infortunio · Indisponibile ora | J11: 29 | K11: Italia | L11: Sx | N11: 1° | O11: Rientro alla 6 (ottobre) | P11: 2 | Q11: 5.75 | R11: 5.75 | S11: 0 | T11: 0 | U11: 0/0 | V11: 34 | W11: 6.1 | X11: 6.81 | Y11: 10 | Z11: 1 | AA11: 4/6 | AB11: Apri | AC11: Apri | AD11: Apri
A12: TOP | B12: 86.7 | C12: FALSE | E12: Barella N. | F12: Inter | G12: 42 | H12: Titolare fisso | I12: Titolare fisso · Consigliato Gazzetta · Garanzia voto · Portatore di bonus | J12: 29 | K12: Italia | L12: Dx | P12: 2 | Q12: 6.5 | R12: 7 | S12: 0 | T12: 1 | U12: 0/0 | V12: 34 | W12: 6.29 | X12: 6.72 | Y12: 3 | Z12: 9 | AA12: 0/0 | AB12: Apri | AC12: Apri | AD12: Apri
A13: TOP | B13: 86.3 | C13: FALSE | E13: Mctominay S. | F13: Napoli | G13: 57 | H13: Titolare probabile | I13: Titolare probabile · Consigliato Gazzetta · Garanzia voto · Portatore di bonus · Rischio infortunio · Indisponibile ora | J13: 29 | K13: Scozia, Inghilterra | L13: Dx | O13: Rientro alla 6 (ottobre) | P13: 2 | Q13: 5.5 | R13: 5.5 | S13: 0 | T13: 0 | U13: 0/0 | V13: 33 | W13: 6.35 | X13: 7.21 | Y13: 10 | Z13: 2 | AA13: 0/1 | AB13: Apri | AC13: Apri | AD13: Apri
A14: TOP | B14: 86.2 | C14: FALSE | E14: De Bruyne K. | F14: Napoli | G14: 48 | H14: Ballottaggio (Vergara A.) | I14: Ballottaggio (Vergara A.) · Calci piazzati | J14: 35 | K14: Belgio | L14: Dx | N14: 1° | P14: 2 | Q14: 6.75 | R14: 8.75 | S14: 1 | T14: 1 | U14: 0/0 | V14: 18 | W14: 6.33 | X14: 7.25 | Y14: 5 | Z14: 2 | AA14: 3/3 | AB14: Apri | AC14: Apri | AD14: Apri
A15: TOP | B15: 85.5 | C15: FALSE | E15: Bernardeschi F. | F15: Bologna | G15: 41 | H15: Titolare fisso | I15: Titolare fisso · Calci piazzati · Consigliato Gazzetta | J15: 32 | K15: Italia | L15: Sx | N15: 2° | P15: 2 | Q15: 6.5 | R15: 6.5 | S15: 0 | T15: 0 | U15: 0/0 | V15: 25 | W15: 6.08 | X15: 6.58 | Y15: 4 | Z15: 2 | AA15: 1/1 | AB15: Apri | AC15: Apri | AD15: Apri
A16: TOP | B16: 85.1 | C16: FALSE | E16: Da Cunha L. | F16: Como | G16: 45 | H16: Titolare fisso | I16: Titolare fisso · Calci piazzati · Garanzia voto · Portatore di bonus | J16: 25 | K16: Francia, Portogallo | L16: Sx | N16: 2° | P16: 3 | Q16: 6.5 | R16: 6.5 | S16: 0 | T16: 0 | U16: 0/0 | V16: 35 | W16: 6.39 | X16: 6.96 | Y16: 6 | Z16: 4 | AA16: 4/4 | AB16: Apri | AC16: Apri | AD16: Apri
A17: TOP | B17: 84.6 | C17: FALSE | D17: ★★ | E17: Atta A. | F17: Fiorentina | G17: 36 | H17: Ballottaggio (Inao Oulai C.) | I17: Ballottaggio (Inao Oulai C.) · Consigliato Gazzetta · Scommessa Gazzetta · Garanzia voto · Portatore di bonus | J17: 23 | K17: Francia, Benin | L17: Dx | P17: 2 | Q17: 4.75 | R17: 4.75 | S17: 0 | T17: 0 | U17: 0/0 | V17: 32 | W17: 6.34 | X17: 6.86 | Y17: 5 | Z17: 3 | AA17: 0/0 | AB17: Apri | AC17: Apri | AD17: Apri
A18: TOP | B18: 84.4 | C18: FALSE | E18: Kone M. | F18: Roma | G18: 41 | H18: Titolare fisso | I18: Titolare fisso · Consigliato Gazzetta | J18: 25 | K18: Francia, Costa d'Avorio | L18: Dx | P18: 2 | Q18: 6.5 | R18: 6.25 | S18: 0 | T18: 0 | U18: 0/0 | V18: 29 | W18: 6.19 | X18: 6.47 | Y18: 2 | Z18: 3 | AA18: 0/0 | AB18: Apri | AC18: Apri | AD18: Apri
A19: TOP | B19: 84.3 | C19: FALSE | E19: Zaniolo N. | F19: Udinese | G19: 48 | H19: Titolare probabile | I19: Titolare probabile · Calci piazzati · Consigliato Gazzetta · Garanzia voto · Portatore di bonus · Rischio infortunio · Indisponibile ora | J19: 27 | K19: Italia | L19: Sx | N19: 1° | O19: Rientro alla 5 (settembre) | P19: 1 | Q19: 6.5 | R19: 6.5 | S19: 0 | T19: 0 | U19: 0/0 | V19: 31 | W19: 6.24 | X19: 6.76 | Y19: 5 | Z19: 5 | AA19: 0/0 | AB19: Apri | AC19: Apri | AD19: Apri
A20: TOP | B20: 84.1 | C20: FALSE | E20: Modric L. | F20: Milan | G20: 42 | H20: Titolare fisso | I20: Titolare fisso · Calci piazzati · Garanzia voto | J20: 40 | K20: Croazia | L20: Ambidestro | N20: 1° | P20: 2 | Q20: 6.25 | R20: 6.25 | S20: 0 | T20: 0 | U20: 0/0 | V20: 33 | W20: 6.5 | X20: 6.71 | Y20: 2 | Z20: 3 | AA20: 0/0 | AB20: Apri | AC20: Apri | AD20: Apri
A21: TOP | B21: 84 | C21: FALSE | D21: ★★ | E21: Santos A. | F21: Napoli | G21: 45 | H21: Titolare fisso | I21: Titolare fisso · Scommessa Gazzetta | J21: 23 | K21: Brasile | L21: Dx | P21: 2 | Q21: 6 | R21: 6 | S21: 0 | T21: 0 | U21: 0/0 | V21: 13 | W21: 6.38 | X21: 7.27 | Y21: 4 | Z21: 0 | AA21: 0/0 | AB21: Apri | AC21: Apri | AD21: Apri
A22: TOP | B22: 83.6 | C22: FALSE | E22: Zaccagni M. | F22: Lazio | G22: 40 | H22: Titolare fisso | I22: Titolare fisso · Calci piazzati · Consigliato Gazzetta | J22: 31 | K22: Italia | L22: Dx | N22: 2° | P22: 2 | Q22: 6 | R22: 5.75 | S22: 0 | T22: 0 | U22: 0/0 | V22: 26 | W22: 5.92 | X22: 6 | Y22: 3 | Z22: 0 | AA22: 0/1 | AB22: Apri | AC22: Apri | AD22: Apri
A23: TOP | B23: 82.3 | C23: FALSE | E23: Conceicao F. | F23: Juventus | G23: 42 | H23: Titolare fisso | I23: Titolare fisso · Garanzia voto · Portatore di bonus | J23: 23 | K23: Portogallo | L23: Sx | P23: 2 | Q23: 6.5 | R23: 7 | S23: 0 | T23: 1 | U23: 0/0 | V23: 31 | W23: 6.24 | X23: 6.65 | Y23: 3 | Z23: 5 | AA23: 0/0 | AB23: Apri | AC23: Apri | AD23: Apri
A24: TOP | B24: 81.5 | C24: FALSE | E24: Ederson | F24: Atalanta | G24: 36 | H24: Titolare fisso | I24: Titolare fisso · Consigliato Gazzetta · Garanzia voto | J24: 27 | K24: Brasile | L24: Dx | P24: 2 | Q24: 6 | R24: 6 | S24: 0 | T24: 0 | U24: 0/0 | V24: 30 | W24: 6.25 | X24: 6.43 | Y24: 2 | Z24: 1 | AA24: 1/1 | AB24: Apri | AC24: Apri | AD24: Apri
A25: SEMITOP | B25: 80.5 | C25: FALSE | E25: Locatelli M. | F25: Juventus | G25: 34 | H25: Titolare fisso | I25: Titolare fisso · Calci piazzati · Consigliato Gazzetta · Garanzia voto | J25: 28 | K25: Italia | L25: Dx | N25: 2° | P25: 2 | Q25: 6.5 | R25: 6.75 | S25: 0 | T25: 1 | U25: 0/0 | V25: 36 | W25: 6.28 | X25: 6.21 | Y25: 1 | Z25: 2 | AA25: 0/1 | AB25: Apri | AC25: Apri | AD25: Apri
A26: SEMITOP | B26: 79.8 | C26: FALSE | E26: Taylor K. | F26: Lazio | G26: 35 | H26: Titolare fisso | I26: Titolare fisso · Consigliato Gazzetta | J26: 24 | K26: Olanda | L26: Sx | P26: 2 | Q26: 6.25 | R26: 6.25 | S26: 0 | T26: 0 | U26: 0/0 | V26: 17 | W26: 6.03 | X26: 6.53 | Y26: 3 | Z26: 2 | AA26: 0/0 | AB26: Apri | AC26: Apri | AD26: Apri
A27: SEMITOP | B27: 77.9 | C27: FALSE | D27: ★★ | E27: Ekkelenkamp J. | F27: Udinese | G27: 33 | H27: Titolare fisso | I27: Titolare fisso · Calci piazzati · Scommessa Gazzetta · Garanzia voto · Portatore di bonus | J27: 26 | K27: Olanda | L27: Dx | N27: 2° | P27: 2 | Q27: 6.75 | R27: 8.75 | S27: 1 | T27: 1 | U27: 0/0 | V27: 31 | W27: 6 | X27: 6.56 | Y27: 5 | Z27: 3 | AA27: 0/0 | AB27: Apri | AC27: Apri | AD27: Apri
A28: SEMITOP | B28: 76.4 | C28: FALSE | E28: Zielinski P. | F28: Inter | G28: 41 | H28: Rotazione / riserva | I28: Rotazione / riserva · Calci piazzati · Consigliato Gazzetta · Garanzia voto · Portatore di bonus | J28: 32 | K28: Polonia | L28: Dx | N28: 3° | P28: 2 | Q28: 6.5 | R28: 8 | S28: 1 | T28: 0 | U28: 0/0 | V28: 31 | W28: 6.35 | X28: 6.89 | Y28: 6 | Z28: 2 | AA28: 1/1 | AB28: Apri | AC28: Apri | AD28: Apri
A29: SEMITOP | B29: 76.3 | C29: FALSE | E29: Perrone M. | F29: Como | G29: 34 | H29: Ballottaggio (Milla L.) | I29: Ballottaggio (Milla L.) · Garanzia voto | J29: 23 | K29: Argentina | L29: Sx | P29: 3 | Q29: 6 | R29: 6 | S29: 0 | T29: 0 | U29: 0/0 | V29: 36 | W29: 6.31 | X29: 6.56 | Y29: 3 | Z29: 4 | AA29: 0/0 | AB29: Apri | AC29: Apri | AD29: Apri
A30: SEMITOP | B30: 75.7 | C30: FALSE | D30: ★★ | E30: Mastantuono F. | F30: Fiorentina | G30: 33 | H30: Titolare fisso | I30: Titolare fisso · Calci piazzati · Consigliato Gazzetta · Under 23 · Novità / ritorno in A | J30: 19 | K30: Argentina | L30: Sx | N30: 1° | P30: 2 | Q30: 5.5 | R30: 5.5 | S30: 0 | T30: 0 | U30: 0/0 | AB30: Apri | AC30: Apri | AD30: Apri
A31: SEMITOP | B31: 75.1 | C31: FALSE | E31: Mckennie W. | F31: Juventus | G31: 41 | H31: Titolare probabile | I31: Titolare probabile · Garanzia voto · Portatore di bonus · Rischio infortunio · Indisponibile ora | J31: 28 | K31: Stati Uniti | L31: Dx | O31: Da valutare | P31: 1 | Q31: 6 | R31: 6 | S31: 0 | T31: 0 | U31: 0/0 | V31: 34 | W31: 6.18 | X31: 6.72 | Y31: 5 | Z31: 6 | AA31: 0/0 | AB31: Apri | AC31: Apri | AD31: Apri
A32: SEMITOP | B32: 74.3 | C32: FALSE | E32: Cristante B. | F32: Roma | G32: 33 | H32: Titolare fisso | I32: Titolare fisso · Garanzia voto | J32: 31 | K32: Italia, Canada | L32: Dx | P32: 2 | Q32: 6.5 | R32: 6.5 | S32: 0 | T32: 0 | U32: 0/0 | V32: 37 | W32: 6.09 | X32: 6.2 | Y32: 2 | Z32: 1 | AA32: 0/0 | AB32: Apri | AC32: Apri | AD32: Apri
A33: SEMITOP | B33: 73.1 | C33: FALSE | E33: Thorstvedt K. | F33: Sassuolo | G33: 38 | H33: Ballottaggio (Adzic V.) | I33: Ballottaggio (Adzic V.) · Consigliato Gazzetta · Garanzia voto | J33: 27 | K33: Norvegia | L33: Sx | P33: 2 | Q33: 6.25 | R33: 6.25 | S33: 0 | T33: 0 | U33: 0/0 | V33: 31 | W33: 6.27 | X33: 6.61 | Y33: 4 | Z33: 3 | AA33: 0/0 | AB33: Apri | AC33: Apri | AD33: Apri
A34: SEMITOP | B34: 72.9 | C34: FALSE | D34: ★★ | E34: Saelemaekers A. | F34: Milan | G34: 39 | H34: Rotazione / riserva | I34: Rotazione / riserva · Calci piazzati · Scommessa Gazzetta · Garanzia voto | J34: 27 | K34: Belgio | L34: Dx | N34: 3° | P34: 2 | Q34: 6.5 | R34: 7 | S34: 0 | T34: 1 | U34: 0/0 | V34: 35 | W34: 6.23 | X34: 6.5 | Y34: 3 | Z34: 3 | AA34: 0/0 | AB34: Apri | AC34: Apri | AD34: Apri
A35: SEMITOP | B35: 72.7 | C35: FALSE | E35: Jones C. | F35: Inter | G35: 38 | H35: Titolare probabile | I35: Titolare probabile · Novità / ritorno in A | J35: 25 | K35: Inghilterra | L35: Dx | P35: 1 | Q35: 6 | R35: 6 | S35: 0 | T35: 0 | U35: 0/0 | AB35: Apri | AC35: Apri | AD35: Apri
